Started by user [8mha:////4KBTASWJbjWEO2b8b2W+ZJbFwJCejfu/iYw42Tli1QbRAAAAlx+LCAAAAAAAAP9b85aBtbiIQTGjNKU4P08vOT+vOD8nVc83PyU1x6OyILUoJzMv2y+/JJUBAhiZGBgqihhk0NSjKDWzXb3RdlLBUSYGJk8GtpzUvPSSDB8G5tKinBIGIZ+sxLJE/ZzEvHT94JKizLx0a6BxUmjGOUNodHsLgAzeEgZu/dLi1CL9xJTczDwACG0V4sAAAAA=[0mJenkins Admin
Running as SYSTEM
Building in workspace /var/jenkins_home/workspace/ansible-test
[ansible-test] $ ansible-playbook /var/jenkins_home/ansible/play.yml -i /var/jenkins_home/ansible/hosts -f 5
/usr/local/lib/python3.5/dist-packages/ansible/parsing/vault/__init__.py:44: CryptographyDeprecationWarning: Python 3.5 support will be dropped in the next release ofcryptography. Please upgrade your Python.
  from cryptography.exceptions import InvalidSignature

PLAY [test1] *******************************************************************

TASK [Gathering Facts] *********************************************************
fatal: [test1]: UNREACHABLE! => {"changed": false, "msg": "Failed to create temporary directory.In some cases, you may have been able to authenticate and did not have permissions on the target directory. Consider changing the remote tmp path in ansible.cfg to a path rooted in \"/tmp\", for more error information use -vvv. Failed command was: ( umask 77 && mkdir -p \"` echo /home/remote_user/.ansible/tmp `\"&& mkdir \"` echo /home/remote_user/.ansible/tmp/ansible-tmp-1601955274.4669664-354-81697612428537 `\" && echo ansible-tmp-1601955274.4669664-354-81697612428537=\"` echo /home/remote_user/.ansible/tmp/ansible-tmp-1601955274.4669664-354-81697612428537 `\" ), exited with result 1", "unreachable": true}

PLAY RECAP *********************************************************************
test1                      : ok=0    changed=0    unreachable=1    failed=0    skipped=0    rescued=0    ignored=0   

Exception ignored in: <function WeakValueDictionary.__init__.<locals>.remove at 0x7f80d1158ae8>
Traceback (most recent call last):
  File "/usr/lib/python3.5/weakref.py", line 117, in remove
TypeError: 'NoneType' object is not callable
Exception ignored in: <function WeakValueDictionary.__init__.<locals>.remove at 0x7f80d1158ae8>
Traceback (most recent call last):
  File "/usr/lib/python3.5/weakref.py", line 117, in remove
TypeError: 'NoneType' object is not callable
Exception ignored in: <function WeakValueDictionary.__init__.<locals>.remove at 0x7f80d1158ae8>
Traceback (most recent call last):
  File "/usr/lib/python3.5/weakref.py", line 117, in remove
TypeError: 'NoneType' object is not callable
Exception ignored in: <function WeakValueDictionary.__init__.<locals>.remove at 0x7f80d1158ae8>
Traceback (most recent call last):
  File "/usr/lib/python3.5/weakref.py", line 117, in remove
TypeError: 'NoneType' object is not callable
Exception ignored in: <function WeakValueDictionary.__init__.<locals>.remove at 0x7f80d1158ae8>
Traceback (most recent call last):
  File "/usr/lib/python3.5/weakref.py", line 117, in remove
TypeError: 'NoneType' object is not callable
Exception ignored in: <function WeakValueDictionary.__init__.<locals>.remove at 0x7f80d1158ae8>
Traceback (most recent call last):
  File "/usr/lib/python3.5/weakref.py", line 117, in remove
TypeError: 'NoneType' object is not callable
Exception ignored in: <function WeakValueDictionary.__init__.<locals>.remove at 0x7f80d1158ae8>
Traceback (most recent call last):
  File "/usr/lib/python3.5/weakref.py", line 117, in remove
TypeError: 'NoneType' object is not callable
Exception ignored in: <function WeakValueDictionary.__init__.<locals>.remove at 0x7f80d1158ae8>
Traceback (most recent call last):
  File "/usr/lib/python3.5/weakref.py", line 117, in remove
TypeError: 'NoneType' object is not callable
Exception ignored in: <function WeakValueDictionary.__init__.<locals>.remove at 0x7f80d1158ae8>
Traceback (most recent call last):
  File "/usr/lib/python3.5/weakref.py", line 117, in remove
TypeError: 'NoneType' object is not callable
Exception ignored in: <function WeakValueDictionary.__init__.<locals>.remove at 0x7f80d1158ae8>
Traceback (most recent call last):
  File "/usr/lib/python3.5/weakref.py", line 117, in remove
TypeError: 'NoneType' object is not callable
Exception ignored in: <function WeakValueDictionary.__init__.<locals>.remove at 0x7f80d1158ae8>
Traceback (most recent call last):
  File "/usr/lib/python3.5/weakref.py", line 117, in remove
TypeError: 'NoneType' object is not callable
Exception ignored in: <function WeakValueDictionary.__init__.<locals>.remove at 0x7f80d1158ae8>
Traceback (most recent call last):
  File "/usr/lib/python3.5/weakref.py", line 117, in remove
TypeError: 'NoneType' object is not callable
Exception ignored in: <function WeakValueDictionary.__init__.<locals>.remove at 0x7f80d1158ae8>
Traceback (most recent call last):
  File "/usr/lib/python3.5/weakref.py", line 117, in remove
TypeError: 'NoneType' object is not callable
Exception ignored in: <function WeakValueDictionary.__init__.<locals>.remove at 0x7f80d1158ae8>
Traceback (most recent call last):
  File "/usr/lib/python3.5/weakref.py", line 117, in remove
TypeError: 'NoneType' object is not callable
Exception ignored in: <function WeakValueDictionary.__init__.<locals>.remove at 0x7f80d1158ae8>
Traceback (most recent call last):
  File "/usr/lib/python3.5/weakref.py", line 117, in remove
TypeError: 'NoneType' object is not callable
Exception ignored in: <function WeakValueDictionary.__init__.<locals>.remove at 0x7f80d1158ae8>
Traceback (most recent call last):
  File "/usr/lib/python3.5/weakref.py", line 117, in remove
TypeError: 'NoneType' object is not callable
Exception ignored in: <function WeakValueDictionary.__init__.<locals>.remove at 0x7f80d1158ae8>
Traceback (most recent call last):
  File "/usr/lib/python3.5/weakref.py", line 117, in remove
TypeError: 'NoneType' object is not callable
Exception ignored in: <function WeakValueDictionary.__init__.<locals>.remove at 0x7f80d1158ae8>
Traceback (most recent call last):
  File "/usr/lib/python3.5/weakref.py", line 117, in remove
TypeError: 'NoneType' object is not callable
Exception ignored in: <function WeakValueDictionary.__init__.<locals>.remove at 0x7f80d1158ae8>
Traceback (most recent call last):
  File "/usr/lib/python3.5/weakref.py", line 117, in remove
TypeError: 'NoneType' object is not callable
Exception ignored in: <function WeakValueDictionary.__init__.<locals>.remove at 0x7f80d1158ae8>
Traceback (most recent call last):
  File "/usr/lib/python3.5/weakref.py", line 117, in remove
TypeError: 'NoneType' object is not callable
Exception ignored in: <function WeakValueDictionary.__init__.<locals>.remove at 0x7f80d1158ae8>
Traceback (most recent call last):
  File "/usr/lib/python3.5/weakref.py", line 117, in remove
TypeError: 'NoneType' object is not callable
Exception ignored in: <function WeakValueDictionary.__init__.<locals>.remove at 0x7f80d1158ae8>
Traceback (most recent call last):
  File "/usr/lib/python3.5/weakref.py", line 117, in remove
TypeError: 'NoneType' object is not callable
Exception ignored in: <function WeakValueDictionary.__init__.<locals>.remove at 0x7f80d1158ae8>
Traceback (most recent call last):
  File "/usr/lib/python3.5/weakref.py", line 117, in remove
TypeError: 'NoneType' object is not callable
Exception ignored in: <function WeakValueDictionary.__init__.<locals>.remove at 0x7f80d1158ae8>
Traceback (most recent call last):
  File "/usr/lib/python3.5/weakref.py", line 117, in remove
TypeError: 'NoneType' object is not callable
Exception ignored in: <function WeakValueDictionary.__init__.<locals>.remove at 0x7f80d1158ae8>
Traceback (most recent call last):
  File "/usr/lib/python3.5/weakref.py", line 117, in remove
TypeError: 'NoneType' object is not callable
Exception ignored in: <function WeakValueDictionary.__init__.<locals>.remove at 0x7f80d1158ae8>
Traceback (most recent call last):
  File "/usr/lib/python3.5/weakref.py", line 117, in remove
TypeError: 'NoneType' object is not callable
Exception ignored in: <function WeakValueDictionary.__init__.<locals>.remove at 0x7f80d1158ae8>
Traceback (most recent call last):
  File "/usr/lib/python3.5/weakref.py", line 117, in remove
TypeError: 'NoneType' object is not callable
Exception ignored in: <function WeakValueDictionary.__init__.<locals>.remove at 0x7f80d1158ae8>
Traceback (most recent call last):
  File "/usr/lib/python3.5/weakref.py", line 117, in remove
TypeError: 'NoneType' object is not callable
FATAL: command execution failed
hudson.AbortException: Ansible playbook execution failed
	at org.jenkinsci.plugins.ansible.AnsiblePlaybookBuilder.perform(AnsiblePlaybookBuilder.java:262)
	at org.jenkinsci.plugins.ansible.AnsiblePlaybookBuilder.perform(AnsiblePlaybookBuilder.java:232)
	at jenkins.tasks.SimpleBuildStep.perform(SimpleBuildStep.java:123)
	at hudson.tasks.BuildStepCompatibilityLayer.perform(BuildStepCompatibilityLayer.java:80)
	at hudson.tasks.BuildStepMonitor$1.perform(BuildStepMonitor.java:20)
	at hudson.model.AbstractBuild$AbstractBuildExecution.perform(AbstractBuild.java:804)
	at hudson.model.Build$BuildExecution.build(Build.java:197)
	at hudson.model.Build$BuildExecution.doRun(Build.java:163)
	at hudson.model.AbstractBuild$AbstractBuildExecution.run(AbstractBuild.java:514)
	at hudson.model.Run.execute(Run.java:1894)
	at hudson.model.FreeStyleBuild.run(FreeStyleBuild.java:43)
	at hudson.model.ResourceController.execute(ResourceController.java:97)
	at hudson.model.Executor.run(Executor.java:428)
ERROR: Ansible playbook execution failed
Finished: FAILURE
